#VRML_SIM R2019a utf8
WorldInfo {
}
Viewpoint {
  orientation -0.988783524491331 -0.1463785841525358 -0.02967240799127645 0.4044154653971425
  position 0.1837303278431467 1.2393428970353069 0.9426600548987711
}
TexturedBackground {
}
TexturedBackgroundLight {
}
Floor {
}
Solid {
  translation 0 0.5 0
  children [
    Shape {
      appearance PBRAppearance {
        baseColor 0 0 0
      }
      geometry Cylinder {
        height 1
        radius 0.15
      }
    }
    HingeJoint {
      endPoint Solid {
        translation 0.25 0.505 0
        children [
          Shape {
            appearance PBRAppearance {
              baseColor 0.9372549019607843 0.1607843137254902 0.1607843137254902
            }
            geometry Box {
              size 0.5 0.01 0.1
            }
          }
        ]
      }
    }
  ]
}
