#VRML_SIM R2019a utf8
WorldInfo {
}
Viewpoint {
  orientation -0.9946539387243956 0.10218076180315516 0.01492092816727636 0.29153676191359296
  position 0.4164645486026147 1.3846433083488685 1.4158530185295515
}
TexturedBackground {
}
TexturedBackgroundLight {
}
Floor {
}
Solid {
  translation 0 0.5 0
  children [
    Shape {
      appearance PBRAppearance {
        baseColor 0 0 0
      }
      geometry Cylinder {
        height 1
        radius 0.15
      }
    }
    HingeJoint {
      jointParameters HingeJointParameters {
        axis 0 1 0
        anchor 0 0.15 0
      }
      endPoint Solid {
        translation 0.25 0.505 0
        children [
          Shape {
            appearance PBRAppearance {
              baseColor 0.9372549019607843 0.1607843137254902 0.1607843137254902
            }
            geometry Box {
              size 0.5 0.01 0.1
            }
          }
          HingeJoint {
            jointParameters HingeJointParameters {
              axis 0 0 1
              anchor 0.25 0 0
              minStop -1
              maxStop 1
            }
            endPoint Solid {
              translation 0.3 0 0
              rotation 0 0 1 0
              children [
                Shape {
                  appearance PBRAppearance {
                    baseColor 0.5411764705882353 0.8862745098039215 0.20392156862745098
                  }
                  geometry Box {
                    size 0.1 0.01 0.1
                  }
                }
                HingeJoint {
                  endPoint Solid {
                    translation 0.125 0 0
                    children [
                      Shape {
                        appearance PBRAppearance {
                          baseColor 0.4470588235294118 0.6235294117647059 0.8117647058823529
                        }
                        geometry Box {
                          size 0.15 0.01 0.1
                        }
                      }
                    ]
                    boundingObject Box {
                      size 0.15 0.01 0.1
                    }
                    physics Physics {
                    }
                  }
                }
              ]
              boundingObject Box {
                size 0.1 0.01 0.1
              }
              physics Physics {
              }
            }
          }
        ]
        boundingObject Box {
          size 0.5 0.01 0.1
        }
        physics Physics {
        }
      }
    }
  ]
}
